{
  "registryname": "basic_portal_fab",
  "localizedname": "Basic Portal Fabricator",
  "color": "808080",
  "parts": [
        {
            "x": -3,
            "y": -2,
            "z": 1,
            "elements": "minecraft:bedrock"
        },
        {
            "x": -4,
            "y": 0,
            "z": 4,
            "elements": "minecraft:bookshelf"
        },
        {
            "x": -2,
            "y": 0,
            "z": 2,
            "elements": "minecraft:enchanting_table"
        },
        {
            "x": -2,
            "y": -2,
            "z": 1,
            "elements": "minecraft:bedrock"
        },
        {
            "x": -3,
            "y": 0,
            "z": 4,
            "elements": "minecraft:bookshelf"
        },
        {
            "x": -3,
            "y": -2,
            "z": 3,
            "elements": "minecraft:bedrock"
        },
        {
            "x": -1,
            "y": -2,
            "z": 1,
            "elements": [
                "minecraft:bedrock"
            ]
        },
        {
            "x": 0,
            "y": 0,
            "z": 2,
            "elements": [
                "minecraft:bookshelf"
            ]
        },
        {
            "x": -2,
            "y": 0,
            "z": 4,
            "elements": [
                "minecraft:bookshelf"
            ]
        },
        {
            "x": -2,
            "y": -2,
            "z": 3,
            "elements": [
                "minecraft:bedrock"
            ]
        },
        {
            "x": -1,
            "y": 0,
            "z": 4,
            "elements": [
                "minecraft:bookshelf"
            ]
        },
        {
            "x": -4,
            "y": 0,
            "z": 0,
            "elements": [
              "modularmachinery:blockcasing@0",
              "modularmachinery:blockinputbus",
              "modularmachinery:blockenergyinputhatch",
              "modularmachinery:blockfluidinputhatch"]
        },
        {
            "x": -1,
            "y": -2,
            "z": 3,
            "elements": "minecraft:bedrock"
        },
        {
            "x": 0,
            "y": 0,
            "z": 4,
            "elements": "minecraft:bookshelf"
        },
        {
            "x": -4,
            "y": 1,
            "z": 2,
            "elements": [
              "modularmachinery:blockinputbus",
              "modularmachinery:blockfluidinputhatch"]
        },
        {
            "x": -4,
            "y": -1,
            "z": 1,
            "elements": [
              "modularmachinery:blockcasing@0"]
        },
        {
            "x": -4,
            "y": 1,
            "z": 4,
            "elements": "minecraft:bookshelf"
        },
        {
            "x": -4,
            "y": -1,
            "z": 3,
            "elements": [
              "modularmachinery:blockcasing"]
        },
        {
            "x": -3,
            "y": 1,
            "z": 4,
            "elements": "minecraft:bookshelf"
        },
        {
            "x": -2,
            "y": 1,
            "z": 4,
            "elements": "minecraft:bookshelf"
        },
        {
            "x": 0,
            "y": 1,
            "z": 2,
            "elements": [
              "modularmachinery:blockcasing",
              "modularmachinery:blockinputbus",
              "modularmachinery:blockenergyinputhatch",
              "modularmachinery:blockfluidinputhatch"]
        },
        {
            "x": 0,
            "y": -1,
            "z": 1,
            "elements": [
              "modularmachinery:blockcasing@0"]
        },
        {
            "x": -1,
            "y": 1,
            "z": 4,
            "elements": "minecraft:bookshelf"
        },
        {
            "x": 0,
            "y": 1,
            "z": 4,
            "elements": "minecraft:bookshelf"
        },
        {
            "x": 0,
            "y": -1,
            "z": 3,
            "elements": [
              "modularmachinery:blockcasing@0"]
        },
        {
            "x": -4,
            "y": 0,
            "z": 1,
            "elements": "minecraft:bookshelf"
        },
        {
            "x": -4,
            "y": 0,
            "z": 3,
            "elements": "minecraft:bookshelf"
        },
        {
            "x": 1,
            "y": 0,
            "z": -1,
            "elements": [
                "cyclicmagic:exp_pylon"
            ]
        },
        {
            "x": -5,
            "y": 0,
            "z": 5,
            "elements": [
                "cyclicmagic:exp_pylon"
            ]
        },
        {
            "x": -3,
            "y": -2,
            "z": 2,
            "elements": [
                "minecraft:bedrock"
            ]
        },
        {
            "x": 0,
            "y": 0,
            "z": 1,
            "elements": [
                "minecraft:bookshelf"
            ]
        },
        {
            "x": -2,
            "y": -2,
            "z": 2,
            "elements": [
                "minecraft:bedrock"
            ]
        },
        {
            "x": -1,
            "y": -2,
            "z": 2,
            "elements": [
                "minecraft:bedrock"
            ]
        },
        {
            "x": 0,
            "y": 0,
            "z": 3,
            "elements": [
                "minecraft:bookshelf"
            ]
        },
        {
            "x": -5,
            "y": 0,
            "z": -1,
            "elements": [
                "cyclicmagic:exp_pylon"
            ]
        },
        {
            "x": 1,
            "y": 0,
            "z": 5,
            "elements": [
                "cyclicmagic:exp_pylon"
            ]
        },
        {
            "x": -4,
            "y": 1,
            "z": 1,
            "elements": [
              "modularmachinery:blockcasing",
              "modularmachinery:blockinputbus",
              "modularmachinery:blockenergyinputhatch",
              "modularmachinery:blockfluidinputhatch"]
        },
        {
            "x": -4,
            "y": 1,
            "z": 3,
            "elements": [
              "modularmachinery:blockcasing",
              "modularmachinery:blockinputbus",
              "modularmachinery:blockenergyinputhatch",
              "modularmachinery:blockfluidinputhatch"]
        },
        {
            "x": -4,
            "y": -1,
            "z": 2,
            "elements": [
              "modularmachinery:blockcasing"]
        },
        {
            "x": 0,
            "y": 1,
            "z": 1,

            "elements": [
              "modularmachinery:blockcasing",
              "modularmachinery:blockinputbus",
              "modularmachinery:blockenergyinputhatch",
              "modularmachinery:blockfluidinputhatch"]
        },
        {
            "x": -4,
            "y": -1,
            "z": 4,
            "elements": [
                "minecraft:bookshelf"
            ]
        },
        {
            "x": -2,
            "y": -1,
            "z": 2,
            "elements": [
                "modularmachinery:blockoutputbus"
            ]
        },
        {
            "x": -3,
            "y": -1,
            "z": 4,
            "elements": [
              "modularmachinery:blockcasing"]
        },
        {
            "x": 0,
            "y": 1,
            "z": 3,
            "elements": [
              "modularmachinery:blockcasing",
              "modularmachinery:blockinputbus",
              "modularmachinery:blockenergyinputhatch",
              "modularmachinery:blockfluidinputhatch"]
        },
        {
            "x": 0,
            "y": -1,
            "z": 2,
            "elements": [
                "modularmachinery:blockcasing@0"
            ]
        },
        {
            "x": -2,
            "y": -1,
            "z": 4,
            "elements": [
                "modularmachinery:blockcasing@0"
            ]
        },
        {
            "x": -1,
            "y": -1,
            "z": 4,
            "elements": [
                "modularmachinery:blockcasing@0"
            ]
        },
        {
            "x": 0,
            "y": -1,
            "z": 4,
            "elements": [
                "minecraft:bookshelf"
            ]
        },
        {
            "x": -4,
            "y": 0,
            "z": 2,
            "elements": [
                "minecraft:bookshelf"
            ]
        }
    ]}
