{
    "registryname": "basic_ebf",
    "localizedname": "Basic Electric Blast Furnace",
    "color": "4DA5C1",
    "parts": [
        {
            "x": -1,
            "y": 0,
            "z": 0,
            "elements": "ebf_casings"
        },
        {
            "x": -1,
            "y": 0,
            "z": 1,
            "elements": "ebf_casings"
        },
        {
            "x": 0,
            "y": 2,
            "z": 2,
            "elements": "basic_casing"
        },
        {
            "x": 1,
            "y": 2,
            "z": 1,
            "elements": "basic_casing"
        },
        {
            "x": 0,
            "y": 0,
            "z": 1,
            "elements": [
                "modularmachinery:blockcasing@5"
            ]
        },
        {
            "x": 1,
            "y": 0,
            "z": 0,
            "elements": "ebf_casings"
        },
        {
            "x": -1,
            "y": 0,
            "z": 2,
            "elements": "ebf_casings"
        },
        {
            "x": 1,
            "y": 2,
            "z": 2,
            "elements": "basic_casing"
        },
        {
            "x": 1,
            "y": 0,
            "z": 1,
            "elements": "ebf_casings"
        },
        {
            "x": 0,
            "y": 0,
            "z": 2,
            "elements": "ebf_casings"
        },
        {
            "x": 1,
            "y": 0,
            "z": 2,
            "elements": "ebf_casings"
        },
        {
            "x": -1,
            "y": 3,
            "z": 0,
            "elements": [
                "modularmachinery:blockcasing@0"
            ]
        },
        {
            "x": 0,
            "y": 3,
            "z": 0,
            "elements": [
                "modularmachinery:blockcasing@0"
            ]
        },
        {
            "x": -1,
            "y": 3,
            "z": 1,
            "elements": [
                "modularmachinery:blockcasing@0"
            ]
        },
        {
            "x": 0,
            "y": 3,
            "z": 1,
            "elements": [
                "modularmachinery:blockcasing@1"
            ]
        },
        {
            "x": 1,
            "y": 3,
            "z": 0,
            "elements": [
                "modularmachinery:blockcasing@0"
            ]
        },
        {
            "x": -1,
            "y": 1,
            "z": 0,
            "elements": "basic_casing"
        },
        {
            "x": -1,
            "y": 3,
            "z": 2,
            "elements": [
                "modularmachinery:blockcasing@0"
            ]
        },
        {
            "x": 0,
            "y": 3,
            "z": 2,
            "elements": [
                "modularmachinery:blockcasing@0"
            ]
        },
        {
            "x": 1,
            "y": 3,
            "z": 1,
            "elements": [
                "modularmachinery:blockcasing@0"
            ]
        },
        {
            "x": 0,
            "y": 1,
            "z": 0,
            "elements": "basic_casing"
        },
        {
            "x": -1,
            "y": 1,
            "z": 1,
            "elements": "basic_casing"
        },
        {
            "x": 1,
            "y": 3,
            "z": 2,
            "elements": [
                "modularmachinery:blockcasing@0"
            ]
        },
        {
            "x": 1,
            "y": 1,
            "z": 0,
            "elements": "basic_casing"
        },
        {
            "x": -1,
            "y": 1,
            "z": 2,
            "elements": "basic_casing"
        },
        {
            "x": 0,
            "y": 1,
            "z": 2,
            "elements": "basic_casing"
        },
        {
            "x": 1,
            "y": 1,
            "z": 1,
            "elements": "basic_casing"
        },
        {
            "x": 1,
            "y": 1,
            "z": 2,
            "elements": "basic_casing"
        },
        {
            "x": -1,
            "y": 2,
            "z": 0,
            "elements": "basic_casing"
        },
        {
            "x": -1,
            "y": 2,
            "z": 1,
            "elements": "basic_casing"
        },
        {
            "x": 0,
            "y": 2,
            "z": 0,
            "elements": "basic_casing"
        },
        {
            "x": -1,
            "y": 2,
            "z": 2,
            "elements": "basic_casing"
        },
        {
            "x": 1,
            "y": 2,
            "z": 0,
            "elements": "basic_casing"
        }
    ]
}