{
    "registryname": "elite_lcr",
    "localizedname": "Elite Large Chemical Reactor",
    "color": "404040",
    "parts": [
        {
            "x": -2,
            "y": 0,
            "z": 2,
            "elements": [
                "extrautils2:decorativeglass@0"
            ]
        },
        {
            "x": -1,
            "y": 0,
            "z": 0,
            "elements": "elite_casing"
        },
        {
            "x": -3,
            "y": -2,
            "z": 1,
            "elements": "lcr_casings"
        },
        {
            "x": -1,
            "y": 0,
            "z": 2,
            "elements": "elite_casing"
        },
        {
            "x": 1,
            "y": 0,
            "z": 0,
            "elements": "elite_casing"
        },
        {
            "x": -2,
            "y": 0,
            "z": 0,
            "elements": [
                "extrautils2:decorativeglass@0"
            ]
        },
        {
            "x": -2,
            "y": -2,
            "z": 1,
            "elements": "elite_casing"
        },
        {
            "x": 0,
            "y": 0,
            "z": 2,
            "elements": "lcr_casings"
        },
        {
            "x": 2,
            "y": 0,
            "z": 0,
            "elements": [
                "extrautils2:decorativeglass@0"
            ]
        },
        {
            "x": -3,
            "y": 0,
            "z": 0,
            "elements": "elite_casing"
        },
        {
            "x": -1,
            "y": -2,
            "z": 1,
            "elements": "elite_casing"
        },
        {
            "x": 1,
            "y": 0,
            "z": 2,
            "elements": "elite_casing"
        },
        {
            "x": 3,
            "y": 0,
            "z": 0,
            "elements": "elite_casing"
        },
        {
            "x": 0,
            "y": -2,
            "z": 1,
            "elements": "elite_casing"
        },
        {
            "x": 2,
            "y": 0,
            "z": 2,
            "elements": [
                "extrautils2:decorativeglass@0"
            ]
        },
        {
            "x": 1,
            "y": -2,
            "z": 1,
            "elements": "elite_casing"
        },
        {
            "x": 3,
            "y": 0,
            "z": 2,
            "elements": "elite_casing"
        },
        {
            "x": 2,
            "y": -2,
            "z": 1,
            "elements": "elite_casing"
        },
        {
            "x": 3,
            "y": -2,
            "z": 1,
            "elements": "lcr_casings"
        },
        {
            "x": 3,
            "y": -1,
            "z": 0,
            "elements": "elite_casing"
        },
        {
            "x": -3,
            "y": 1,
            "z": 0,
            "elements": [
                "modularmachinery:blockcasing@0"
            ]
        },
        {
            "x": 2,
            "y": -1,
            "z": 0,
            "elements": [
                "extrautils2:decorativeglass@0"
            ]
        },
        {
            "x": -2,
            "y": 1,
            "z": 0,
            "elements": [
                "modularmachinery:blockcasing@0"
            ]
        },
        {
            "x": 1,
            "y": -1,
            "z": 0,
            "elements": "lcr_casings"
        },
        {
            "x": -1,
            "y": 1,
            "z": 0,
            "elements": [
                "modularmachinery:blockcasing@0"
            ]
        },
        {
            "x": -3,
            "y": 1,
            "z": 2,
            "elements": [
                "modularmachinery:blockcasing@0"
            ]
        },
        {
            "x": 0,
            "y": -1,
            "z": 0,
            "elements": "lcr_casings"
        },
        {
            "x": 0,
            "y": 1,
            "z": 0,
            "elements": [
                "modularmachinery:blockcasing@0"
            ]
        },
        {
            "x": -2,
            "y": 1,
            "z": 2,
            "elements": [
                "modularmachinery:blockcasing@0"
            ]
        },
        {
            "x": -1,
            "y": -1,
            "z": 0,
            "elements": "lcr_casings"
        },
        {
            "x": 1,
            "y": 1,
            "z": 0,
            "elements": [
                "modularmachinery:blockcasing@0"
            ]
        },
        {
            "x": -1,
            "y": 1,
            "z": 2,
            "elements": [
                "modularmachinery:blockcasing@0"
            ]
        },
        {
            "x": -2,
            "y": -1,
            "z": 0,
            "elements": [
                "extrautils2:decorativeglass@0"
            ]
        },
        {
            "x": 2,
            "y": 1,
            "z": 0,
            "elements": [
                "modularmachinery:blockcasing@0"
            ]
        },
        {
            "x": 0,
            "y": 1,
            "z": 2,
            "elements": [
                "modularmachinery:blockcasing@0"
            ]
        },
        {
            "x": -3,
            "y": -1,
            "z": 0,
            "elements": "elite_casing"
        },
        {
            "x": -1,
            "y": -1,
            "z": 1,
            "elements": [
                "xtones:korp@12"
            ]
        },
        {
            "x": 3,
            "y": 1,
            "z": 0,
            "elements": [
                "modularmachinery:blockcasing@0"
            ]
        },
        {
            "x": 1,
            "y": 1,
            "z": 2,
            "elements": [
                "modularmachinery:blockcasing@0"
            ]
        },
        {
            "x": 0,
            "y": -1,
            "z": 1,
            "elements": [
                "xtones:korp@12"
            ]
        },
        {
            "x": 2,
            "y": 1,
            "z": 2,
            "elements": [
                "modularmachinery:blockcasing@0"
            ]
        },
        {
            "x": 1,
            "y": -1,
            "z": 1,
            "elements": [
                "xtones:korp@12"
            ]
        },
        {
            "x": 3,
            "y": 1,
            "z": 2,
            "elements": [
                "modularmachinery:blockcasing@0"
            ]
        },
        {
            "x": 3,
            "y": -1,
            "z": 1,
            "elements": [
                "extrautils2:decorativeglass@0"
            ]
        },
        {
            "x": 3,
            "y": -2,
            "z": 0,
            "elements": [
                "modularmachinery:blockcasing@0"
            ]
        },
        {
            "x": 2,
            "y": -2,
            "z": 0,
            "elements": [
                "modularmachinery:blockcasing@0"
            ]
        },
        {
            "x": 1,
            "y": -2,
            "z": 0,
            "elements": [
                "modularmachinery:blockcasing@0"
            ]
        },
        {
            "x": 0,
            "y": -2,
            "z": 0,
            "elements": [
                "modularmachinery:blockcasing@0"
            ]
        },
        {
            "x": -1,
            "y": -2,
            "z": 0,
            "elements": [
                "modularmachinery:blockcasing@0"
            ]
        },
        {
            "x": -2,
            "y": -2,
            "z": 0,
            "elements": [
                "modularmachinery:blockcasing@0"
            ]
        },
        {
            "x": -3,
            "y": -2,
            "z": 0,
            "elements": [
                "modularmachinery:blockcasing@0"
            ]
        },
        {
            "x": -1,
            "y": 0,
            "z": 1,
            "elements": [
                "immersiveengineering:metal_decoration0@0"
            ]
        },
        {
            "x": -3,
            "y": -2,
            "z": 2,
            "elements": [
                "modularmachinery:blockcasing@0"
            ]
        },
        {
            "x": 0,
            "y": 0,
            "z": 1,
            "elements": [
                "immersiveengineering:metal_decoration0@2"
            ]
        },
        {
            "x": -2,
            "y": -2,
            "z": 2,
            "elements": [
                "modularmachinery:blockcasing@0"
            ]
        },
        {
            "x": 1,
            "y": 0,
            "z": 1,
            "elements": [
                "immersiveengineering:metal_decoration0@2"
            ]
        },
        {
            "x": -1,
            "y": -2,
            "z": 2,
            "elements": [
                "modularmachinery:blockcasing@0"
            ]
        },
        {
            "x": 0,
            "y": -2,
            "z": 2,
            "elements": [
                "modularmachinery:blockcasing@0"
            ]
        },
        {
            "x": 3,
            "y": 0,
            "z": 1,
            "elements": [
                "extrautils2:decorativeglass@0"
            ]
        },
        {
            "x": 1,
            "y": -2,
            "z": 2,
            "elements": [
                "modularmachinery:blockcasing@0"
            ]
        },
        {
            "x": 2,
            "y": -2,
            "z": 2,
            "elements": [
                "modularmachinery:blockcasing@0"
            ]
        },
        {
            "x": 3,
            "y": -2,
            "z": 2,
            "elements": [
                "modularmachinery:blockcasing@0"
            ]
        },
        {
            "x": -3,
            "y": 1,
            "z": 1,
            "elements": [
                "modularmachinery:blockcasing@0"
            ]
        },
        {
            "x": -2,
            "y": 1,
            "z": 1,
            "elements": [
                "modularmachinery:blockcasing@1"
            ]
        },
        {
            "x": -1,
            "y": 1,
            "z": 1,
            "elements": "elite_casing"
        },
        {
            "x": 0,
            "y": 1,
            "z": 1,
            "elements": "elite_casing"
        },
        {
            "x": -3,
            "y": -1,
            "z": 2,
            "elements": "elite_casing"
        },
        {
            "x": 1,
            "y": 1,
            "z": 1,
            "elements": "elite_casing"
        },
        {
            "x": -2,
            "y": -1,
            "z": 2,
            "elements": [
                "extrautils2:decorativeglass@0"
            ]
        },
        {
            "x": 2,
            "y": 1,
            "z": 1,
            "elements": [
                "modularmachinery:blockcasing@1"
            ]
        },
        {
            "x": -1,
            "y": -1,
            "z": 2,
            "elements": "elite_casing"
        },
        {
            "x": 3,
            "y": 1,
            "z": 1,
            "elements": [
                "modularmachinery:blockcasing@0"
            ]
        },
        {
            "x": 0,
            "y": -1,
            "z": 2,
            "elements": "lcr_casings"
        },
        {
            "x": 1,
            "y": -1,
            "z": 2,
            "elements": "elite_casing"
        },
        {
            "x": 2,
            "y": -1,
            "z": 2,
            "elements": [
                "extrautils2:decorativeglass@0"
            ]
        },
        {
            "x": 3,
            "y": -1,
            "z": 2,
            "elements": "elite_casing"
        },
        {
            "x": -3,
            "y": 0,
            "z": 2,
            "elements": "elite_casing"
        },
        {
            "x": -3,
            "y": 0,
            "z": 1,
            "elements": [
                "extrautils2:decorativeglass@0"
            ]
        },
        {
            "x": -3,
            "y": -1,
            "z": 1,
            "elements": [
                "extrautils2:decorativeglass@0"
            ]
        }
    ]
}