{
    "registryname": "portal_fabricator",
    "localizedname": "Portal Fabricator",
    "color": "ffffff",
    "parts": [
        {
            "x": 0,
            "y": 0,
            "z": 0,
            "nbt": {"casingColor":"16730368","items":{"inventoryArray":[{"holderEmpty":"1b","holderId":"0"},{"holderEmpty":"1b","holderId":"1"}],"outSlots":,"miscSlots":,"inSlots":,"sides":},"status":"0"},
            "elements": [
                "modularmachinery:blockcontroller@1"
            ]
        },
        {
            "x": -1,
            "y": 0,
            "z": 0,
            "elements": [
                "minecraft:glass@0"
            ]
        },
        {
            "x": 1,
            "y": 2,
            "z": 1,
            "nbt": {"Item":{"id":"minecraft:air","Count":"0b","Damage":"0s"},"Empty":"","amount":"0"},
            "elements": [
                "skyresources:crucible@0"
            ]
        },
        {
            "x": -2,
            "y": 0,
            "z": 0,
            "elements": [
                "minecraft:brick_block@0"
            ]
        },
        {
            "x": 2,
            "y": 2,
            "z": 1,
            "elements": [
                "minecraft:glass@0"
            ]
        },
        {
            "x": 1,
            "y": 0,
            "z": 0,
            "elements": [
                "minecraft:glass@0"
            ]
        },
        {
            "x": 2,
            "y": 0,
            "z": 0,
            "elements": [
                "minecraft:brick_block@0"
            ]
        },
        {
            "x": -2,
            "y": 0,
            "z": 4,
            "elements": [
                "minecraft:brick_block@0"
            ]
        },
        {
            "x": -1,
            "y": 0,
            "z": 4,
            "elements": [
                "minecraft:glass@0"
            ]
        },
        {
            "x": 0,
            "y": 0,
            "z": 4,
            "elements": [
                "minecraft:glass@0"
            ]
        },
        {
            "x": 1,
            "y": 0,
            "z": 4,
            "elements": [
                "minecraft:glass@0"
            ]
        },
        {
            "x": 2,
            "y": 0,
            "z": 4,
            "elements": [
                "minecraft:brick_block@0"
            ]
        },
        {
            "x": -2,
            "y": 3,
            "z": 1,
            "elements": [
                "minecraft:brick_stairs@0"
            ]
        },
        {
            "x": 2,
            "y": -1,
            "z": 0,
            "elements": [
                "minecraft:brick_block@0"
            ]
        },
        {
            "x": -2,
            "y": 1,
            "z": 0,
            "elements": [
                "minecraft:brick_block@0"
            ]
        },
        {
            "x": -1,
            "y": 3,
            "z": 1,
            "elements": [
                "minecraft:netherrack@0"
            ]
        },
        {
            "x": 1,
            "y": -1,
            "z": 0,
            "elements": [
                "minecraft:brick_block@0"
            ]
        },
        {
            "x": 0,
            "y": -1,
            "z": 0,
            "elements": [
                "minecraft:brick_block@0"
            ]
        },
        {
            "x": 0,
            "y": 3,
            "z": 1,
            "elements": [
                "minecraft:netherrack@0"
            ]
        },
        {
            "x": -1,
            "y": 1,
            "z": 0,
            "elements": [
                "minecraft:glass@0"
            ]
        },
        {
            "x": 1,
            "y": 3,
            "z": 1,
            "elements": [
                "minecraft:netherrack@0"
            ]
        },
        {
            "x": 0,
            "y": 1,
            "z": 0,
            "elements": [
                "minecraft:glass@0"
            ]
        },
        {
            "x": -1,
            "y": -1,
            "z": 0,
            "elements": [
                "minecraft:brick_block@0"
            ]
        },
        {
            "x": -2,
            "y": -1,
            "z": 0,
            "elements": [
                "minecraft:brick_block@0"
            ]
        },
        {
            "x": 2,
            "y": 3,
            "z": 1,
            "elements": [
                "minecraft:brick_stairs@1"
            ]
        },
        {
            "x": 1,
            "y": 1,
            "z": 0,
            "elements": [
                "minecraft:glass@0"
            ]
        },
        {
            "x": -2,
            "y": 1,
            "z": 4,
            "elements": [
                "minecraft:brick_block@0"
            ]
        },
        {
            "x": 2,
            "y": 1,
            "z": 0,
            "elements": [
                "minecraft:brick_block@0"
            ]
        },
        {
            "x": -2,
            "y": -1,
            "z": 3,
            "elements": [
                "minecraft:brick_block@0"
            ]
        },
        {
            "x": -1,
            "y": 1,
            "z": 4,
            "elements": [
                "minecraft:glass@0"
            ]
        },
        {
            "x": 0,
            "y": 1,
            "z": 4,
            "elements": [
                "minecraft:glass@0"
            ]
        },
        {
            "x": -1,
            "y": -1,
            "z": 3,
            "elements": [
                "minecraft:brick_block@0"
            ]
        },
        {
            "x": 0,
            "y": -1,
            "z": 3,
            "elements": [
                "minecraft:brick_block@0"
            ]
        },
        {
            "x": 1,
            "y": 1,
            "z": 4,
            "elements": [
                "minecraft:glass@0"
            ]
        },
        {
            "x": 2,
            "y": 1,
            "z": 4,
            "elements": [
                "minecraft:brick_block@0"
            ]
        },
        {
            "x": 1,
            "y": -1,
            "z": 3,
            "elements": [
                "minecraft:brick_block@0"
            ]
        },
        {
            "x": 2,
            "y": -1,
            "z": 3,
            "elements": [
                "minecraft:brick_block@0"
            ]
        },
        {
            "x": -2,
            "y": 2,
            "z": 0,
            "elements": [
                "minecraft:brick_block@0"
            ]
        },
        {
            "x": -1,
            "y": 4,
            "z": 1,
            "elements": [
                "minecraft:fire@15"
            ]
        },
        {
            "x": 0,
            "y": 4,
            "z": 1,
            "elements": [
                "minecraft:fire@15"
            ]
        },
        {
            "x": -1,
            "y": 2,
            "z": 0,
            "elements": [
                "minecraft:glass@0"
            ]
        },
        {
            "x": 1,
            "y": 4,
            "z": 1,
            "elements": [
                "minecraft:fire@15"
            ]
        },
        {
            "x": 0,
            "y": 2,
            "z": 0,
            "elements": [
                "minecraft:glass@0"
            ]
        },
        {
            "x": 1,
            "y": 2,
            "z": 0,
            "elements": [
                "minecraft:glass@0"
            ]
        },
        {
            "x": -2,
            "y": 2,
            "z": 4,
            "elements": [
                "minecraft:brick_block@0"
            ]
        },
        {
            "x": 2,
            "y": 2,
            "z": 0,
            "elements": [
                "minecraft:brick_block@0"
            ]
        },
        {
            "x": -2,
            "y": 0,
            "z": 3,
            "elements": [
                "minecraft:glass@0"
            ]
        },
        {
            "x": -1,
            "y": 2,
            "z": 4,
            "elements": [
                "minecraft:glass@0"
            ]
        },
        {
            "x": 0,
            "y": 2,
            "z": 4,
            "elements": [
                "minecraft:glass@0"
            ]
        },
        {
            "x": -1,
            "y": 0,
            "z": 3,
            "nbt": {"MachineData":{"curHU":"0.0f","huTick":"0.0f","itemHU":"0.0f"},"inv":{"Size":"1","Items":[]},"Empty":"","Energy":"0","pSignal":"0","Machine":{"id":"skyresources:combustionheater","Count":"1b","Damage":"12s"}},
            "elements": [
                "skyresources:casing@12"
            ]
        },
        {
            "x": 0,
            "y": 0,
            "z": 3,
            "nbt": {"MachineData":{"curHU":"0.0f","huTick":"0.0f","itemHU":"0.0f"},"inv":{"Size":"1","Items":[]},"Empty":"","Energy":"0","pSignal":"0","Machine":{"id":"skyresources:combustionheater","Count":"1b","Damage":"12s"}},
            "elements": [
                "skyresources:casing@12"
            ]
        },
        {
            "x": 1,
            "y": 2,
            "z": 4,
            "elements": [
                "minecraft:glass@0"
            ]
        },
        {
            "x": 2,
            "y": 2,
            "z": 4,
            "elements": [
                "minecraft:brick_block@0"
            ]
        },
        {
            "x": 1,
            "y": 0,
            "z": 3,
            "nbt": {"MachineData":{"curHU":"0.0f","huTick":"0.0f","itemHU":"0.0f"},"inv":{"Size":"1","Items":[]},"Empty":"","Energy":"0","pSignal":"0","Machine":{"id":"skyresources:combustionheater","Count":"1b","Damage":"12s"}},
            "elements": [
                "skyresources:casing@12"
            ]
        },
        {
            "x": 2,
            "y": 0,
            "z": 3,
            "elements": [
                "minecraft:glass@0"
            ]
        },
        {
            "x": -2,
            "y": 3,
            "z": 0,
            "elements": [
                "minecraft:brick_stairs@0"
            ]
        },
        {
            "x": -1,
            "y": 3,
            "z": 0,
            "elements": [
                "minecraft:brick_stairs@2"
            ]
        },
        {
            "x": 0,
            "y": 3,
            "z": 0,
            "elements": [
                "minecraft:brick_stairs@2"
            ]
        },
        {
            "x": 1,
            "y": 3,
            "z": 0,
            "elements": [
                "minecraft:brick_stairs@2"
            ]
        },
        {
            "x": -2,
            "y": 3,
            "z": 4,
            "elements": [
                "minecraft:brick_stairs@0"
            ]
        },
        {
            "x": 2,
            "y": 3,
            "z": 0,
            "elements": [
                "minecraft:brick_stairs@2"
            ]
        },
        {
            "x": -2,
            "y": 1,
            "z": 3,
            "elements": [
                "minecraft:glass@0"
            ]
        },
        {
            "x": -1,
            "y": 3,
            "z": 4,
            "elements": [
                "minecraft:brick_stairs@3"
            ]
        },
        {
            "x": 0,
            "y": 3,
            "z": 4,
            "elements": [
                "minecraft:brick_stairs@3"
            ]
        },
        {
            "x": -2,
            "y": -1,
            "z": 2,
            "elements": [
                "minecraft:brick_block@0"
            ]
        },
        {
            "x": -1,
            "y": 1,
            "z": 3,
            "elements": [
                "contenttweaker:glass-_slime_composite_molten@0"
            ]
        },
        {
            "x": 1,
            "y": 3,
            "z": 4,
            "elements": [
                "minecraft:brick_stairs@3"
            ]
        },
        {
            "x": 0,
            "y": 1,
            "z": 3,
            "elements": [
                "contenttweaker:glass-_slime_composite_molten@0"
            ]
        },
        {
            "x": -1,
            "y": -1,
            "z": 2,
            "elements": [
                "minecraft:brick_block@0"
            ]
        },
        {
            "x": 0,
            "y": -1,
            "z": 2,
            "elements": [
                "minecraft:brick_block@0"
            ]
        },
        {
            "x": 2,
            "y": 3,
            "z": 4,
            "elements": [
                "minecraft:brick_stairs@3"
            ]
        },
        {
            "x": 1,
            "y": 1,
            "z": 3,
            "elements": [
                "contenttweaker:glass-_slime_composite_molten@0"
            ]
        },
        {
            "x": 2,
            "y": 1,
            "z": 3,
            "elements": [
                "minecraft:glass@0"
            ]
        },
        {
            "x": 1,
            "y": -1,
            "z": 2,
            "elements": [
                "minecraft:brick_block@0"
            ]
        },
        {
            "x": 2,
            "y": -1,
            "z": 2,
            "elements": [
                "minecraft:brick_block@0"
            ]
        },
        {
            "x": -2,
            "y": 2,
            "z": 3,
            "elements": [
                "minecraft:glass@0"
            ]
        },
        {
            "x": -2,
            "y": 0,
            "z": 2,
            "nbt": {"busSize":"0","casingColor":"16730368","inventory":{"inventoryArray":[{"holderEmpty":"1b","holderId":"0"}],"outSlots":,"miscSlots":,"inSlots":,"sides":}},
            "elements": [
                "modularmachinery:blockoutputbus@0"
            ]
        },
        {
            "x": -1,
            "y": 2,
            "z": 3,
            "nbt": {"Item":{"id":"minecraft:air","Count":"0b","Damage":"0s"},"Empty":"","amount":"0"},
            "elements": [
                "skyresources:crucible@0"
            ]
        },
        {
            "x": 0,
            "y": 2,
            "z": 3,
            "nbt": {"Item":{"id":"minecraft:air","Count":"0b","Damage":"0s"},"Empty":"","amount":"0"},
            "elements": [
                "skyresources:crucible@0"
            ]
        },
        {
            "x": -1,
            "y": 0,
            "z": 2,
            "nbt": {"MachineData":{"curHU":"0.0f","huTick":"0.0f","itemHU":"0.0f"},"inv":{"Size":"1","Items":[]},"Empty":"","Energy":"0","pSignal":"0","Machine":{"id":"skyresources:combustionheater","Count":"1b","Damage":"12s"}},
            "elements": [
                "skyresources:casing@12"
            ]
        },
        {
            "x": 0,
            "y": 0,
            "z": 2,
            "nbt": {"MachineData":{"curHU":"0.0f","huTick":"0.0f","itemHU":"0.0f"},"inv":{"Size":"1","Items":[]},"Empty":"","Energy":"0","pSignal":"0","Machine":{"id":"skyresources:combustionheater","Count":"1b","Damage":"12s"}},
            "elements": [
                "skyresources:casing@12"
            ]
        },
        {
            "x": 1,
            "y": 2,
            "z": 3,
            "nbt": {"Item":{"id":"minecraft:air","Count":"0b","Damage":"0s"},"Empty":"","amount":"0"},
            "elements": [
                "skyresources:crucible@0"
            ]
        },
        {
            "x": 2,
            "y": 2,
            "z": 3,
            "elements": [
                "minecraft:glass@0"
            ]
        },
        {
            "x": 1,
            "y": 0,
            "z": 2,
            "nbt": {"MachineData":{"curHU":"0.0f","huTick":"0.0f","itemHU":"0.0f"},"inv":{"Size":"1","Items":[]},"Empty":"","Energy":"0","pSignal":"0","Machine":{"id":"skyresources:combustionheater","Count":"1b","Damage":"12s"}},
            "elements": [
                "skyresources:casing@12"
            ]
        },
        {
            "x": 2,
            "y": 0,
            "z": 2,
            "nbt": {"busSize":"0","casingColor":"16730368","inventory":{"inventoryArray":[{"holderEmpty":"1b","holderId":"0"}],"outSlots":,"miscSlots":,"inSlots":,"sides":}},
            "elements": [
                "modularmachinery:blockinputbus@0"
            ]
        },
        {
            "x": -2,
            "y": 3,
            "z": 3,
            "elements": [
                "minecraft:brick_stairs@0"
            ]
        },
        {
            "x": -2,
            "y": 1,
            "z": 2,
            "nbt": {"input":"0b","size":"0","casingColor":"16730368","tank":{"Empty":"","gasTag":{"Empty":""}}},
            "elements": [
                "modularmachinery:blockfluidoutputhatch@0"
            ]
        },
        {
            "x": -1,
            "y": 3,
            "z": 3,
            "elements": [
                "minecraft:netherrack@0"
            ]
        },
        {
            "x": 0,
            "y": 3,
            "z": 3,
            "elements": [
                "minecraft:netherrack@0"
            ]
        },
        {
            "x": -2,
            "y": -1,
            "z": 1,
            "elements": [
                "minecraft:brick_block@0"
            ]
        },
        {
            "x": -1,
            "y": 1,
            "z": 2,
            "elements": [
                "contenttweaker:glass-_slime_composite_molten@0"
            ]
        },
        {
            "x": 1,
            "y": 3,
            "z": 3,
            "elements": [
                "minecraft:netherrack@0"
            ]
        },
        {
            "x": 0,
            "y": 1,
            "z": 2,
            "elements": [
                "contenttweaker:glass-_slime_composite_molten@0"
            ]
        },
        {
            "x": -1,
            "y": -1,
            "z": 1,
            "elements": [
                "minecraft:brick_block@0"
            ]
        },
        {
            "x": 0,
            "y": -1,
            "z": 1,
            "elements": [
                "minecraft:brick_block@0"
            ]
        },
        {
            "x": 2,
            "y": 3,
            "z": 3,
            "elements": [
                "minecraft:brick_stairs@1"
            ]
        },
        {
            "x": 1,
            "y": 1,
            "z": 2,
            "elements": [
                "contenttweaker:glass-_slime_composite_molten@0"
            ]
        },
        {
            "x": 2,
            "y": 1,
            "z": 2,
            "nbt": {"input":"1b","size":"0","casingColor":"16730368","tank":{"Empty":"","gasTag":{"Empty":""}}},
            "elements": [
                "modularmachinery:blockfluidinputhatch@0"
            ]
        },
        {
            "x": 1,
            "y": -1,
            "z": 1,
            "elements": [
                "minecraft:brick_block@0"
            ]
        },
        {
            "x": 2,
            "y": -1,
            "z": 1,
            "elements": [
                "minecraft:brick_block@0"
            ]
        },
        {
            "x": -2,
            "y": 2,
            "z": 2,
            "elements": [
                "minecraft:glass@0"
            ]
        },
        {
            "x": -1,
            "y": 4,
            "z": 3,
            "elements": [
                "minecraft:fire@15"
            ]
        },
        {
            "x": 0,
            "y": 4,
            "z": 3,
            "elements": [
                "minecraft:fire@15"
            ]
        },
        {
            "x": -2,
            "y": 0,
            "z": 1,
            "elements": [
                "minecraft:glass@0"
            ]
        },
        {
            "x": -1,
            "y": 2,
            "z": 2,
            "nbt": {"Item":{"id":"minecraft:air","Count":"0b","Damage":"0s"},"Empty":"","amount":"0"},
            "elements": [
                "skyresources:crucible@0"
            ]
        },
        {
            "x": 1,
            "y": 4,
            "z": 3,
            "elements": [
                "minecraft:fire@15"
            ]
        },
        {
            "x": 0,
            "y": 2,
            "z": 2,
            "nbt": {"Item":{"id":"minecraft:air","Count":"0b","Damage":"0s"},"Empty":"","amount":"0"},
            "elements": [
                "skyresources:crucible@0"
            ]
        },
        {
            "x": -1,
            "y": 0,
            "z": 1,
            "nbt": {"MachineData":{"curHU":"0.0f","huTick":"0.0f","itemHU":"0.0f"},"inv":{"Size":"1","Items":[]},"Empty":"","Energy":"0","pSignal":"0","Machine":{"id":"skyresources:combustionheater","Count":"1b","Damage":"12s"}},
            "elements": [
                "skyresources:casing@12"
            ]
        },
        {
            "x": 0,
            "y": 0,
            "z": 1,
            "nbt": {"MachineData":{"curHU":"0.0f","huTick":"0.0f","itemHU":"0.0f"},"inv":{"Size":"1","Items":[]},"Empty":"","Energy":"0","pSignal":"0","Machine":{"id":"skyresources:combustionheater","Count":"1b","Damage":"12s"}},
            "elements": [
                "skyresources:casing@12"
            ]
        },
        {
            "x": 1,
            "y": 2,
            "z": 2,
            "nbt": {"Item":{"id":"minecraft:air","Count":"0b","Damage":"0s"},"Empty":"","amount":"0"},
            "elements": [
                "skyresources:crucible@0"
            ]
        },
        {
            "x": 2,
            "y": 2,
            "z": 2,
            "elements": [
                "minecraft:glass@0"
            ]
        },
        {
            "x": 1,
            "y": 0,
            "z": 1,
            "nbt": {"MachineData":{"curHU":"0.0f","huTick":"0.0f","itemHU":"0.0f"},"inv":{"Size":"1","Items":[]},"Empty":"","Energy":"0","pSignal":"0","Machine":{"id":"skyresources:combustionheater","Count":"1b","Damage":"12s"}},
            "elements": [
                "skyresources:casing@12"
            ]
        },
        {
            "x": 2,
            "y": 0,
            "z": 1,
            "elements": [
                "minecraft:glass@0"
            ]
        },
        {
            "x": -2,
            "y": 3,
            "z": 2,
            "elements": [
                "minecraft:brick_stairs@0"
            ]
        },
        {
            "x": -2,
            "y": 1,
            "z": 1,
            "elements": [
                "minecraft:glass@0"
            ]
        },
        {
            "x": -1,
            "y": 3,
            "z": 2,
            "elements": [
                "minecraft:netherrack@0"
            ]
        },
        {
            "x": 0,
            "y": 3,
            "z": 2,
            "elements": [
                "minecraft:netherrack@0"
            ]
        },
        {
            "x": -1,
            "y": 1,
            "z": 1,
            "elements": [
                "contenttweaker:glass-_slime_composite_molten@0"
            ]
        },
        {
            "x": 1,
            "y": 3,
            "z": 2,
            "elements": [
                "minecraft:netherrack@0"
            ]
        },
        {
            "x": 0,
            "y": 1,
            "z": 1,
            "elements": [
                "contenttweaker:glass-_slime_composite_molten@0"
            ]
        },
        {
            "x": 2,
            "y": 3,
            "z": 2,
            "elements": [
                "minecraft:brick_stairs@1"
            ]
        },
        {
            "x": 1,
            "y": 1,
            "z": 1,
            "elements": [
                "contenttweaker:glass-_slime_composite_molten@0"
            ]
        },
        {
            "x": 2,
            "y": 1,
            "z": 1,
            "elements": [
                "minecraft:glass@0"
            ]
        },
        {
            "x": -2,
            "y": -1,
            "z": 4,
            "elements": [
                "minecraft:brick_block@0"
            ]
        },
        {
            "x": -1,
            "y": -1,
            "z": 4,
            "elements": [
                "minecraft:brick_block@0"
            ]
        },
        {
            "x": 0,
            "y": -1,
            "z": 4,
            "elements": [
                "minecraft:brick_block@0"
            ]
        },
        {
            "x": 1,
            "y": -1,
            "z": 4,
            "elements": [
                "minecraft:brick_block@0"
            ]
        },
        {
            "x": 2,
            "y": -1,
            "z": 4,
            "elements": [
                "minecraft:brick_block@0"
            ]
        },
        {
            "x": 10,
            "y": -1,
            "z": 4,
            "elements": [
                "minecraft:brick_block@0"
            ]
        },
        {
            "x": -2,
            "y": 2,
            "z": 1,
            "elements": [
                "minecraft:glass@0"
            ]
        },
        {
            "x": -1,
            "y": 4,
            "z": 2,
            "elements": [
                "minecraft:fire@15"
            ]
        },
        {
            "x": 0,
            "y": 4,
            "z": 2,
            "elements": [
                "minecraft:fire@15"
            ]
        },
        {
            "x": -1,
            "y": 2,
            "z": 1,
            "nbt": {"Item":{"id":"minecraft:air","Count":"0b","Damage":"0s"},"Empty":"","amount":"0"},
            "elements": [
                "skyresources:crucible@0"
            ]
        },
        {
            "x": 1,
            "y": 4,
            "z": 2,
            "elements": [
                "minecraft:fire@15"
            ]
        },
        {
            "x": 0,
            "y": 2,
            "z": 1,
            "nbt": {"Item":{"id":"minecraft:air","Count":"0b","Damage":"0s"},"Empty":"","amount":"0"},
            "elements": [
                "skyresources:crucible@0"
            ]
        }
    ]}